Workbook

Sheet Raw_Data
A1: Order_ID | B1: Order_Date | C1: Product_ID | D1: Employee_ID | E1: City | F1: Payment_Method | G1: Quantity | H1: Discount | I1: Sales_Provided | K1: Original data, untouched (120 rows incl. 3 duplicates, spacing/case issues). Do not edit.
A2: O001 | B2: 46109 | C2: P102 | D2: E001 | E2: Lucknow | F2: Card | G2: 3 | H2: 0 | I2: 54000
A3: O002 | B3: 46050 | C3: P109 | D3: E002 | E3: Delhi | F3: UPI | G3: 1 | H3: 0 | I3: 3500
A4: O003 | B4: 46098 | C4: P104 | D4: E001 | E4: Lucknow | F4: Net Banking | G4: 4 | H4: 0.15 | I4: 25500
A5: O004 | B5: 46042 | C5: P105 | D5: E001 | E5: Lucknow | F5: Net Banking | G5: 6 | H5: 0.1 | I5: 64800
A6: O005 | B6: 46131 | C6: P104 | D6: E006 | E6: Mumbai | F6: Net Banking | G6: 2 | H6: 0.1 | I6: 13500
A7: O006 | B7: 46033 | C7: P106 | D7: E005 | E7: Mumbai | F7: Net Banking | G7: 2 | H7: 0.15 | I7: 2040
A8: O007 | B8: 46028 | C8: P109 | D8: E005 | E8: Mumbai | F8: Cash | G8: 4 | H8: 0 | I8: 14000
A9: O008 | B9: 46081 | C9: P104 | D9: E005 | E9: Lucknow | F9: UPI | G9: 7 | H9: 0.1 | I9: 47250
A10: O009 | B10: 46100 | C10: P106 | D10: E003 | E10: Mumbai | F10: Card | G10: 5 | H10: 0 | I10: 6000
A11: O010 | B11: 46110 | C11: P103 | D11: E004 | E11: Lucknow | F11: Net Banking | G11: 5 | H11: 0.05 | I11: 11875
A12: O011 | B12: 46057 | C12: P106 | D12: E001 | E12: Lucknow | F12: UPI | G12: 6 | H12: 0.15 | I12: 6120
A13: O012 | B13: 46073 | C13: P102 | D13: E004 | E13: Mumbai | F13: Cash | G13: 4 | H13: 0.15 | I13: 61200
... A121: O120 | B121: 46142 | C121: P104 | D121: E002 | E121: Delhi | F121: UPI | G121: 3 | H121: 0.15 | I121: 19125

Sheet Clean_Data
A1: OrdeID | B1: Order_Date | C1: Product_ID | D1: Employee_ID | E1: City | F1: Payment_Method | G1: Quantity | H1: Discount | I1: Sales_Provided | J1: Product_Name | K1: Category | L1: Unit_Price | M1: Employee_Name | N1: Employee_Base_City | O1: Gross_Sales | P1: Discount_Amount | Q1: Net_Sales | R1: Cost | S1: Profit | T1: Profit_Margin | U1: Month | V1: Sales_Check | W1: City_vs_Base | Y1: Columns J:W are formulas. Net_Sales ties to Sales_Provided (Sales_Check = 0).
A2: O001 | B2: 46109 | C2: P102 | D2: E001 | E2: Lucknow | F2: Card | G2: 3 | H2: 0 | I2: 54000 | J2: =INDEX(Product_Master!$B$2:$B$11,MATCH(C2,Product_Master!$A$2:$A$11,0)) -> Monitor | K2: =INDEX(Product_Master!$C$2:$C$11,MATCH(C2,Product_Master!$A$2:$A$11,0)) -> Electronics | L2: =INDEX(Product_Master!$D$2:$D$11,MATCH(C2,Product_Master!$A$2:$A$11,0)) -> 18000 | M2: =INDEX(Employee_Master!$B$2:$B$9,MATCH(D2,Employee_Master!$A$2:$A$9,0)) -> Rahul | N2: =INDEX(Employee_Master!$C$2:$C$9,MATCH(D2,Employee_Master!$A$2:$A$9,0)) -> Lucknow | O2: =G2*L2 -> 54000 | P2: =O2*H2 -> 0 | Q2: =O2-P2 -> 54000 | R2: =O2*INDEX(Assumptions!$B$5:$B$8,MATCH(K2,Assumptions!$A$5:$A$8,0)) -> 40500 | S2: =Q2-R2 -> 13500 | T2: =IF(Q2=0,0,S2/Q2) -> 0.25 | U2: =DATE(YEAR(B2),MONTH(B2),1) -> 46082 | V2: =Q2-I2 -> 0 | W2: =IF(E2=N2,"Same","Different") -> Same
A3: O002 | B3: 46050 | C3: P109 | D3: E002 | E3: Delhi | F3: UPI | G3: 1 | H3: 0 | I3: 3500 | J3: =INDEX(Product_Master!$B$2:$B$11,MATCH(C3,Product_Master!$A$2:$A$11,0)) -> Headphones | K3: =INDEX(Product_Master!$C$2:$C$11,MATCH(C3,Product_Master!$A$2:$A$11,0)) -> Electronics | L3: =INDEX(Product_Master!$D$2:$D$11,MATCH(C3,Product_Master!$A$2:$A$11,0)) -> 3500 | M3: =INDEX(Employee_Master!$B$2:$B$9,MATCH(D3,Employee_Master!$A$2:$A$9,0)) -> Priya | N3: =INDEX(Employee_Master!$C$2:$C$9,MATCH(D3,Employee_Master!$A$2:$A$9,0)) -> Delhi | O3: =G3*L3 -> 3500 | P3: =O3*H3 -> 0 | Q3: =O3-P3 -> 3500 | R3: =O3*INDEX(Assumptions!$B$5:$B$8,MATCH(K3,Assumptions!$A$5:$A$8,0)) -> 2625 | S3: =Q3-R3 -> 875 | T3: =IF(Q3=0,0,S3/Q3) -> 0.25 | U3: =DATE(YEAR(B3),MONTH(B3),1) -> 46023 | V3: =Q3-I3 -> 0 | W3: =IF(E3=N3,"Same","Different") -> Same
A4: O003 | B4: 46098 | C4: P104 | D4: E001 | E4: Lucknow | F4: Net Banking | G4: 4 | H4: 0.15 | I4: 25500 | J4: =INDEX(Product_Master!$B$2:$B$11,MATCH(C4,Product_Master!$A$2:$A$11,0)) -> Office Chair | K4: =INDEX(Product_Master!$C$2:$C$11,MATCH(C4,Product_Master!$A$2:$A$11,0)) -> Furniture | L4: =INDEX(Product_Master!$D$2:$D$11,MATCH(C4,Product_Master!$A$2:$A$11,0)) -> 7500 | M4: =INDEX(Employee_Master!$B$2:$B$9,MATCH(D4,Employee_Master!$A$2:$A$9,0)) -> Rahul | N4: =INDEX(Employee_Master!$C$2:$C$9,MATCH(D4,Employee_Master!$A$2:$A$9,0)) -> Lucknow | O4: =G4*L4 -> 30000 | P4: =O4*H4 -> 4500 | Q4: =O4-P4 -> 25500 | R4: =O4*INDEX(Assumptions!$B$5:$B$8,MATCH(K4,Assumptions!$A$5:$A$8,0)) -> 19500 | S4: =Q4-R4 -> 6000 | T4: =IF(Q4=0,0,S4/Q4) -> 0.23529412 | U4: =DATE(YEAR(B4),MONTH(B4),1) -> 46082 | V4: =Q4-I4 -> 0 | W4: =IF(E4=N4,"Same","Different") -> Same
A5: O004 | B5: 46042 | C5: P105 | D5: E001 | E5: Lucknow | F5: Net Banking | G5: 6 | H5: 0.1 | I5: 64800 | J5: =INDEX(Product_Master!$B$2:$B$11,MATCH(C5,Product_Master!$A$2:$A$11,0)) -> Desk | K5: =INDEX(Product_Master!$C$2:$C$11,MATCH(C5,Product_Master!$A$2:$A$11,0)) -> Furniture | L5: =INDEX(Product_Master!$D$2:$D$11,MATCH(C5,Product_Master!$A$2:$A$11,0)) -> 12000 | M5: =INDEX(Employee_Master!$B$2:$B$9,MATCH(D5,Employee_Master!$A$2:$A$9,0)) -> Rahul | N5: =INDEX(Employee_Master!$C$2:$C$9,MATCH(D5,Employee_Master!$A$2:$A$9,0)) -> Lucknow | O5: =G5*L5 -> 72000 | P5: =O5*H5 -> 7200 | Q5: =O5-P5 -> 64800 | R5: =O5*INDEX(Assumptions!$B$5:$B$8,MATCH(K5,Assumptions!$A$5:$A$8,0)) -> 46800 | S5: =Q5-R5 -> 18000 | T5: =IF(Q5=0,0,S5/Q5) -> 0.27777778 | U5: =DATE(YEAR(B5),MONTH(B5),1) -> 46023 | V5: =Q5-I5 -> 0 | W5: =IF(E5=N5,"Same","Different") -> Same
A6: O005 | B6: 46131 | C6: P104 | D6: E006 | E6: Mumbai | F6: Net Banking | G6: 2 | H6: 0.1 | I6: 13500 | J6: =INDEX(Product_Master!$B$2:$B$11,MATCH(C6,Product_Master!$A$2:$A$11,0)) -> Office Chair | K6: =INDEX(Product_Master!$C$2:$C$11,MATCH(C6,Product_Master!$A$2:$A$11,0)) -> Furniture | L6: =INDEX(Product_Master!$D$2:$D$11,MATCH(C6,Product_Master!$A$2:$A$11,0)) -> 7500 | M6: =INDEX(Employee_Master!$B$2:$B$9,MATCH(D6,Employee_Master!$A$2:$A$9,0)) -> Ayesha | N6: =INDEX(Employee_Master!$C$2:$C$9,MATCH(D6,Employee_Master!$A$2:$A$9,0)) -> Mumbai | O6: =G6*L6 -> 15000 | P6: =O6*H6 -> 1500 | Q6: =O6-P6 -> 13500 | R6: =O6*INDEX(Assumptions!$B$5:$B$8,MATCH(K6,Assumptions!$A$5:$A$8,0)) -> 9750 | S6: =Q6-R6 -> 3750 | T6: =IF(Q6=0,0,S6/Q6) -> 0.27777778 | U6: =DATE(YEAR(B6),MONTH(B6),1) -> 46113 | V6: =Q6-I6 -> 0 | W6: =IF(E6=N6,"Same","Different") -> Same
A7: O006 | B7: 46033 | C7: P106 | D7: E005 | E7: Mumbai | F7: Net Banking | G7: 2 | H7: 0.15 | I7: 2040 | J7: =INDEX(Product_Master!$B$2:$B$11,MATCH(C7,Product_Master!$A$2:$A$11,0)) -> T-Shirt | K7: =INDEX(Product_Master!$C$2:$C$11,MATCH(C7,Product_Master!$A$2:$A$11,0)) -> Clothing | L7: =INDEX(Product_Master!$D$2:$D$11,MATCH(C7,Product_Master!$A$2:$A$11,0)) -> 1200 | M7: =INDEX(Employee_Master!$B$2:$B$9,MATCH(D7,Employee_Master!$A$2:$A$9,0)) -> Hamza | N7: =INDEX(Employee_Master!$C$2:$C$9,MATCH(D7,Employee_Master!$A$2:$A$9,0)) -> Delhi | O7: =G7*L7 -> 2400 | P7: =O7*H7 -> 360 | Q7: =O7-P7 -> 2040 | R7: =O7*INDEX(Assumptions!$B$5:$B$8,MATCH(K7,Assumptions!$A$5:$A$8,0)) -> 1200 | S7: =Q7-R7 -> 840 | T7: =IF(Q7=0,0,S7/Q7) -> 0.41176471 | U7: =DATE(YEAR(B7),MONTH(B7),1) -> 46023 | V7: =Q7-I7 -> 0 | W7: =IF(E7=N7,"Same","Different") -> Different
A8: O007 | B8: 46028 | C8: P109 | D8: E005 | E8: Mumbai | F8: Cash | G8: 4 | H8: 0 | I8: 14000 | J8: =INDEX(Product_Master!$B$2:$B$11,MATCH(C8,Product_Master!$A$2:$A$11,0)) -> Headphones | K8: =INDEX(Product_Master!$C$2:$C$11,MATCH(C8,Product_Master!$A$2:$A$11,0)) -> Electronics | L8: =INDEX(Product_Master!$D$2:$D$11,MATCH(C8,Product_Master!$A$2:$A$11,0)) -> 3500 | M8: =INDEX(Employee_Master!$B$2:$B$9,MATCH(D8,Employee_Master!$A$2:$A$9,0)) -> Hamza | N8: =INDEX(Employee_Master!$C$2:$C$9,MATCH(D8,Employee_Master!$A$2:$A$9,0)) -> Delhi | O8: =G8*L8 -> 14000 | P8: =O8*H8 -> 0 | Q8: =O8-P8 -> 14000 | R8: =O8*INDEX(Assumptions!$B$5:$B$8,MATCH(K8,Assumptions!$A$5:$A$8,0)) -> 10500 | S8: =Q8-R8 -> 3500 | T8: =IF(Q8=0,0,S8/Q8) -> 0.25 | U8: =DATE(YEAR(B8),MONTH(B8),1) -> 46023 | V8: =Q8-I8 -> 0 | W8: =IF(E8=N8,"Same","Different") -> Different
A9: O008 | B9: 46081 | C9: P104 | D9: E005 | E9: Lucknow | F9: UPI | G9: 7 | H9: 0.1 | I9: 47250 | J9: =INDEX(Product_Master!$B$2:$B$11,MATCH(C9,Product_Master!$A$2:$A$11,0)) -> Office Chair | K9: =INDEX(Product_Master!$C$2:$C$11,MATCH(C9,Product_Master!$A$2:$A$11,0)) -> Furniture | L9: =INDEX(Product_Master!$D$2:$D$11,MATCH(C9,Product_Master!$A$2:$A$11,0)) -> 7500 | M9: =INDEX(Employee_Master!$B$2:$B$9,MATCH(D9,Employee_Master!$A$2:$A$9,0)) -> Hamza | N9: =INDEX(Employee_Master!$C$2:$C$9,MATCH(D9,Employee_Master!$A$2:$A$9,0)) -> Delhi | O9: =G9*L9 -> 52500 | P9: =O9*H9 -> 5250 | Q9: =O9-P9 -> 47250 | R9: =O9*INDEX(Assumptions!$B$5:$B$8,MATCH(K9,Assumptions!$A$5:$A$8,0)) -> 34125 | S9: =Q9-R9 -> 13125 | T9: =IF(Q9=0,0,S9/Q9) -> 0.27777778 | U9: =DATE(YEAR(B9),MONTH(B9),1) -> 46054 | V9: =Q9-I9 -> 0 | W9: =IF(E9=N9,"Same","Different") -> Different
A10: O009 | B10: 46100 | C10: P106 | D10: E003 | E10: Mumbai | F10: Card | G10: 5 | H10: 0 | I10: 6000 | J10: =INDEX(Product_Master!$B$2:$B$11,MATCH(C10,Product_Master!$A$2:$A$11,0)) -> T-Shirt | K10: =INDEX(Product_Master!$C$2:$C$11,MATCH(C10,Product_Master!$A$2:$A$11,0)) -> Clothing | L10: =INDEX(Product_Master!$D$2:$D$11,MATCH(C10,Product_Master!$A$2:$A$11,0)) -> 1200 | M10: =INDEX(Employee_Master!$B$2:$B$9,MATCH(D10,Employee_Master!$A$2:$A$9,0)) -> Arman | N10: =INDEX(Employee_Master!$C$2:$C$9,MATCH(D10,Employee_Master!$A$2:$A$9,0)) -> Mumbai | O10: =G10*L10 -> 6000 | P10: =O10*H10 -> 0 | Q10: =O10-P10 -> 6000 | R10: =O10*INDEX(Assumptions!$B$5:$B$8,MATCH(K10,Assumptions!$A$5:$A$8,0)) -> 3000 | S10: =Q10-R10 -> 3000 | T10: =IF(Q10=0,0,S10/Q10) -> 0.5 | U10: =DATE(YEAR(B10),MONTH(B10),1) -> 46082 | V10: =Q10-I10 -> 0 | W10: =IF(E10=N10,"Same","Different") -> Same
A11: O010 | B11: 46110 | C11: P103 | D11: E004 | E11: Lucknow | F11: Net Banking | G11: 5 | H11: 0.05 | I11: 11875 | J11: =INDEX(Product_Master!$B$2:$B$11,MATCH(C11,Product_Master!$A$2:$A$11,0)) -> Keyboard | K11: =INDEX(Product_Master!$C$2:$C$11,MATCH(C11,Product_Master!$A$2:$A$11,0)) -> Electronics | L11: =INDEX(Product_Master!$D$2:$D$11,MATCH(C11,Product_Master!$A$2:$A$11,0)) -> 2500 | M11: =INDEX(Employee_Master!$B$2:$B$9,MATCH(D11,Employee_Master!$A$2:$A$9,0)) -> Sara | N11: =INDEX(Employee_Master!$C$2:$C$9,MATCH(D11,Employee_Master!$A$2:$A$9,0)) -> Lucknow | O11: =G11*L11 -> 12500 | P11: =O11*H11 -> 625 | Q11: =O11-P11 -> 11875 | R11: =O11*INDEX(Assumptions!$B$5:$B$8,MATCH(K11,Assumptions!$A$5:$A$8,0)) -> 9375 | S11: =Q11-R11 -> 2500 | T11: =IF(Q11=0,0,S11/Q11) -> 0.21052632 | U11: =DATE(YEAR(B11),MONTH(B11),1) -> 46082 | V11: =Q11-I11 -> 0 | W11: =IF(E11=N11,"Same","Different") -> Same
A12: O011 | B12: 46057 | C12: P106 | D12: E001 | E12: Lucknow | F12: UPI | G12: 6 | H12: 0.15 | I12: 6120 | J12: =INDEX(Product_Master!$B$2:$B$11,MATCH(C12,Product_Master!$A$2:$A$11,0)) -> T-Shirt | K12: =INDEX(Product_Master!$C$2:$C$11,MATCH(C12,Product_Master!$A$2:$A$11,0)) -> Clothing | L12: =INDEX(Product_Master!$D$2:$D$11,MATCH(C12,Product_Master!$A$2:$A$11,0)) -> 1200 | M12: =INDEX(Employee_Master!$B$2:$B$9,MATCH(D12,Employee_Master!$A$2:$A$9,0)) -> Rahul | N12: =INDEX(Employee_Master!$C$2:$C$9,MATCH(D12,Employee_Master!$A$2:$A$9,0)) -> Lucknow | O12: =G12*L12 -> 7200 | P12: =O12*H12 -> 1080 | Q12: =O12-P12 -> 6120 | R12: =O12*INDEX(Assumptions!$B$5:$B$8,MATCH(K12,Assumptions!$A$5:$A$8,0)) -> 3600 | S12: =Q12-R12 -> 2520 | T12: =IF(Q12=0,0,S12/Q12) -> 0.41176471 | U12: =DATE(YEAR(B12),MONTH(B12),1) -> 46054 | V12: =Q12-I12 -> 0 | W12: =IF(E12=N12,"Same","Different") -> Same
A13: O012 | B13: 46073 | C13: P102 | D13: E004 | E13: Mumbai | F13: Cash | G13: 4 | H13: 0.15 | I13: 61200 | J13: =INDEX(Product_Master!$B$2:$B$11,MATCH(C13,Product_Master!$A$2:$A$11,0)) -> Monitor | K13: =INDEX(Product_Master!$C$2:$C$11,MATCH(C13,Product_Master!$A$2:$A$11,0)) -> Electronics | L13: =INDEX(Product_Master!$D$2:$D$11,MATCH(C13,Product_Master!$A$2:$A$11,0)) -> 18000 | M13: =INDEX(Employee_Master!$B$2:$B$9,MATCH(D13,Employee_Master!$A$2:$A$9,0)) -> Sara | N13: =INDEX(Employee_Master!$C$2:$C$9,MATCH(D13,Employee_Master!$A$2:$A$9,0)) -> Lucknow | O13: =G13*L13 -> 72000 | P13: =O13*H13 -> 10800 | Q13: =O13-P13 -> 61200 | R13: =O13*INDEX(Assumptions!$B$5:$B$8,MATCH(K13,Assumptions!$A$5:$A$8,0)) -> 54000 | S13: =Q13-R13 -> 7200 | T13: =IF(Q13=0,0,S13/Q13) -> 0.11764706 | U13: =DATE(YEAR(B13),MONTH(B13),1) -> 46054 | V13: =Q13-I13 -> 0 | W13: =IF(E13=N13,"Same","Different") -> Different
... A118: O120 | B118: 46142 | C118: P104 | D118: E002 | E118: Delhi | F118: UPI | G118: 3 | H118: 0.15 | I118: 19125 | J118: =INDEX(Product_Master!$B$2:$B$11,MATCH(C118,Product_Master!$A$2:$A$11,0)) -> Office Chair | K118: =INDEX(Product_Master!$C$2:$C$11,MATCH(C118,Product_Master!$A$2:$A$11,0)) -> Furniture | L118: =INDEX(Product_Master!$D$2:$D$11,MATCH(C118,Product_Master!$A$2:$A$11,0)) -> 7500 | M118: =INDEX(Employee_Master!$B$2:$B$9,MATCH(D118,Employee_Master!$A$2:$A$9,0)) -> Priya | N118: =INDEX(Employee_Master!$C$2:$C$9,MATCH(D118,Employee_Master!$A$2:$A$9,0)) -> Delhi | O118: =G118*L118 -> 22500 | P118: =O118*H118 -> 3375 | Q118: =O118-P118 -> 19125 | R118: =O118*INDEX(Assumptions!$B$5:$B$8,MATCH(K118,Assumptions!$A$5:$A$8,0)) -> 14625 | S118: =Q118-R118 -> 4500 | T118: =IF(Q118=0,0,S118/Q118) -> 0.23529412 | U118: =DATE(YEAR(B118),MONTH(B118),1) -> 46113 | V118: =Q118-I118 -> 0 | W118: =IF(E118=N118,"Same","Different") -> Same

Sheet Analysis
A1: Analysis
A2: KPIs, business questions (formulas) and written insights. Figures in INR.
A4: A. KPI Summary
A5: KPI | B5: Value | D5: How it is calculated
A6: Raw records (Raw_Data) | B6: =COUNTA(Raw_Data!$A$2:$A$121) -> 120 | D6: Count of rows in the original data
A7: Duplicate records removed | B7: =B6-B8 -> 3 | D7: Raw records minus clean records
A8: Clean records / Total Orders | B8: =COUNTA(Clean_Data!$A$2:$A$118) -> 117 | D8: Unique Order_IDs after de-duplication
A9: Date range - first order | B9: =MIN(Clean_Data!$B$2:$B$118) -> 46023 | D9: MIN of Order_Date
A10: Date range - last order | B10: =MAX(Clean_Data!$B$2:$B$118) -> 46142 | D10: MAX of Order_Date
A11: Total Quantity | B11: =SUM(Clean_Data!$G$2:$G$118) -> 546 | D11: SUM of Quantity
A12: Gross Sales | B12: =SUM(Clean_Data!$O$2:$O$118) -> 4053000 | D12: Quantity x Unit_Price
A13: Total Discount Given | B13: =SUM(Clean_Data!$P$2:$P$118) -> 243480 | D13: Gross Sales x Discount %
A14: Total Sales (Net Sales) | B14: =SUM(Clean_Data!$Q$2:$Q$118) -> 3809520 | D14: Gross Sales - Discount
A15: Total Cost (assumed) | B15: =SUM(Clean_Data!$R$2:$R$118) -> 2838400 | D15: Category cost % (see Assumptions)
A16: Total Profit (assumed cost basis) | B16: =SUM(Clean_Data!$S$2:$S$118) -> 971120 | D16: Net Sales - Cost
A17: Profit Margin | B17: =IF(B14=0,0,B16/B14) -> 0.25491925 | D17: Profit / Net Sales
A18: Average Order Value | B18: =AVERAGE(Clean_Data!$Q$2:$Q$118) -> 32560 | D18: AVERAGE of Net_Sales per order
A19: Average Quantity per Order | B19: =AVERAGE(Clean_Data!$G$2:$G$118) -> 4.6666667 | D19: AVERAGE of Quantity
A20: Average Discount % | B20: =AVERAGE(Clean_Data!$H$2:$H$118) -> 0.078632479 | D20: AVERAGE of Discount
A21: Effective discount (Discount / Gross) | B21: =IF(B12=0,0,B13/B12) -> 0.060074019 | D21: Total Discount / Gross Sales
A24: B. Business Questions
A25: Question | B25: Answer | C25: Value | D25: Formula used
A26: Highest-sales product | B26: =INDEX(Pivot_Analysis!$A$23:$A$32,MATCH(MAX(Pivot_Analysis!$E$23:$E$32),Pivot_Analysis!$E$23:$E$32,0)) -> Laptop | C26: =MAX(Pivot_Analysis!$E$23:$E$32) -> 1391500 | D26: INDEX/MATCH on MAX of product Net Sales
A27: Lowest-sales product | B27: =INDEX(Pivot_Analysis!$A$23:$A$32,MATCH(MIN(Pivot_Analysis!$E$23:$E$32),Pivot_Analysis!$E$23:$E$32,0)) -> T-Shirt | C27: =MIN(Pivot_Analysis!$E$23:$E$32) -> 74460 | D27: INDEX/MATCH on MIN
A28: Highest-sales employee | B28: =INDEX(Pivot_Analysis!$A$38:$A$45,MATCH(MAX(Pivot_Analysis!$E$38:$E$45),Pivot_Analysis!$E$38:$E$45,0)) -> Priya | C28: =MAX(Pivot_Analysis!$E$38:$E$45) -> 809345 | D28: INDEX/MATCH on MAX
A29: Highest-sales city | B29: =INDEX(Pivot_Analysis!$A$6:$A$8,MATCH(MAX(Pivot_Analysis!$E$6:$E$8),Pivot_Analysis!$E$6:$E$8,0)) -> Delhi | C29: =MAX(Pivot_Analysis!$E$6:$E$8) -> 1818000 | D29: INDEX/MATCH on MAX
A30: Highest-sales category | B30: =INDEX(Pivot_Analysis!$A$14:$A$17,MATCH(MAX(Pivot_Analysis!$E$14:$E$17),Pivot_Analysis!$E$14:$E$17,0)) -> Electronics | C30: =MAX(Pivot_Analysis!$E$14:$E$17) -> 2352425 | D30: INDEX/MATCH on MAX
A31: Highest-profit category | B31: =INDEX(Pivot_Analysis!$A$14:$A$17,MATCH(MAX(Pivot_Analysis!$F$14:$F$17),Pivot_Analysis!$F$14:$F$17,0)) -> Electronics | C31: =MAX(Pivot_Analysis!$F$14:$F$17) -> 510050 | D31: INDEX/MATCH on MAX of Profit
A32: Best month (Net Sales) | B32: =TEXT(INDEX(Pivot_Analysis!$A$51:$A$54,MATCH(MAX(Pivot_Analysis!$E$51:$E$54),Pivot_Analysis!$E$51:$E$54,0)),"mmm yyyy") -> Jan 2026 | C32: =MAX(Pivot_Analysis!$E$51:$E$54) -> 1307050 | D32: INDEX/MATCH on MAX
A33: Weakest month (Net Sales) | B33: =TEXT(INDEX(Pivot_Analysis!$A$51:$A$54,MATCH(MIN(Pivot_Analysis!$E$51:$E$54),Pivot_Analysis!$E$51:$E$54,0)),"mmm yyyy") -> Apr 2026 | C33: =MIN(Pivot_Analysis!$E$51:$E$54) -> 456040 | D33: INDEX/MATCH on MIN
A34: Top City-Category combination | B34: =INDEX(Pivot_Analysis!$A$69:$A$71,SUMPRODUCT((Pivot_Analysis!$B$69:$E$71=MAX(Pivot_Analysis!$B$69:$E$71))*(ROW(Pivot_Analysis!$B$69:$E$71)-68)))&" - "&INDEX(Pivot_Analysis!$B$68:$E$68,SUMPRODUCT((Pivot_Analysis!$B$69:$E$71=MAX(Pivot_Analysis!$B$69:$E$71))*(COLUMN(Pivot_Analysis!$B$69:$E$71)-1))) -> Delhi - Electronics | C34: =MAX(Pivot_Analysis!$B$69:$E$71) -> 1298150 | D34: MAX over City x Category matrix
A35: Orders with discount >= 10% (COUNTIFS) | C35: =COUNTIFS(Clean_Data!$H$2:$H$118,">=0.1") -> 59 | D35: COUNTIFS on Discount
A36: Orders with no discount (COUNTIFS) | C36: =COUNTIFS(Clean_Data!$H$2:$H$118,0) -> 28 | D36: COUNTIFS on Discount
A37: Electronics orders in Delhi (COUNTIFS) | C37: =COUNTIFS(Clean_Data!$E$2:$E$118,"Delhi",Clean_Data!$K$2:$K$118,"Electronics") -> 17 | D37: COUNTIFS on City and Category
A38: UPI orders (COUNTIFS) | C38: =COUNTIFS(Clean_Data!$F$2:$F$118,"UPI") -> 29 | D38: COUNTIFS on Payment_Method
A39: Orders sold outside employee Base City (COUNTIFS) | C39: =COUNTIFS(Clean_Data!$W$2:$W$118,"Different") -> 21 | D39: COUNTIFS on City_vs_Base flag
A40: Avg order value - Electronics (AVERAGEIFS) | C40: =AVERAGEIFS(Clean_Data!$Q$2:$Q$118,Clean_Data!$K$2:$K$118,"Electronics") -> 73513.281 | D40: AVERAGEIFS on Category
A41: Avg order value - discounted orders (AVERAGEIFS) | C41: =AVERAGEIFS(Clean_Data!$Q$2:$Q$118,Clean_Data!$H$2:$H$118,">0") -> 25011.461 | D41: AVERAGEIFS on Discount > 0
A42: Avg order value - non-discounted orders (AVERAGEIFS) | C42: =AVERAGEIFS(Clean_Data!$Q$2:$Q$118,Clean_Data!$H$2:$H$118,0) -> 56553.571 | D42: AVERAGEIFS on Discount = 0
A43: Avg discount % - Delhi orders (AVERAGEIFS) | C43: =AVERAGEIFS(Clean_Data!$H$2:$H$118,Clean_Data!$E$2:$E$118,"Delhi") -> 0.074545455 | D43: AVERAGEIFS on City
...

Sheet Pivot_Analysis
A1: Pivot Analysis
A2: Formula-driven summary tables (SUMIFS / COUNTIFS / AVERAGEIFS) on Clean_Data. All values update with the data.
A4: 1. Sales by City
A5: City | B5: Orders | C5: Quantity | D5: Gross Sales | E5: Net Sales | F5: Profit | G5: Avg Order Value | H5: Sales Share
A6: Delhi | B6: =COUNTIFS(Clean_Data!$E$2:$E$118,$A6) -> 55 | C6: =SUMIFS(Clean_Data!$G$2:$G$118,Clean_Data!$E$2:$E$118,$A6) -> 243 | D6: =SUMIFS(Clean_Data!$O$2:$O$118,Clean_Data!$E$2:$E$118,$A6) -> 1916600 | E6: =SUMIFS(Clean_Data!$Q$2:$Q$118,Clean_Data!$E$2:$E$118,$A6) -> 1818000 | F6: =SUMIFS(Clean_Data!$S$2:$S$118,Clean_Data!$E$2:$E$118,$A6) -> 458640 | G6: =IFERROR(AVERAGEIFS(Clean_Data!$Q$2:$Q$118,Clean_Data!$E$2:$E$118,$A6),0) -> 33054.545 | H6: =IF($E$9=0,0,E6/$E$9) -> 0.47722548
A7: Lucknow | B7: =COUNTIFS(Clean_Data!$E$2:$E$118,$A7) -> 35 | C7: =SUMIFS(Clean_Data!$G$2:$G$118,Clean_Data!$E$2:$E$118,$A7) -> 170 | D7: =SUMIFS(Clean_Data!$O$2:$O$118,Clean_Data!$E$2:$E$118,$A7) -> 1343000 | E7: =SUMIFS(Clean_Data!$Q$2:$Q$118,Clean_Data!$E$2:$E$118,$A7) -> 1271200 | F7: =SUMIFS(Clean_Data!$S$2:$S$118,Clean_Data!$E$2:$E$118,$A7) -> 335530 | G7: =IFERROR(AVERAGEIFS(Clean_Data!$Q$2:$Q$118,Clean_Data!$E$2:$E$118,$A7),0) -> 36320 | H7: =IF($E$9=0,0,E7/$E$9) -> 0.33369033
A8: Mumbai | B8: =COUNTIFS(Clean_Data!$E$2:$E$118,$A8) -> 27 | C8: =SUMIFS(Clean_Data!$G$2:$G$118,Clean_Data!$E$2:$E$118,$A8) -> 133 | D8: =SUMIFS(Clean_Data!$O$2:$O$118,Clean_Data!$E$2:$E$118,$A8) -> 793400 | E8: =SUMIFS(Clean_Data!$Q$2:$Q$118,Clean_Data!$E$2:$E$118,$A8) -> 720320 | F8: =SUMIFS(Clean_Data!$S$2:$S$118,Clean_Data!$E$2:$E$118,$A8) -> 176950 | G8: =IFERROR(AVERAGEIFS(Clean_Data!$Q$2:$Q$118,Clean_Data!$E$2:$E$118,$A8),0) -> 26678.519 | H8: =IF($E$9=0,0,E8/$E$9) -> 0.18908419
A9: Total | B9: =SUM(B6:B8) -> 117 | C9: =SUM(C6:C8) -> 546 | D9: =SUM(D6:D8) -> 4053000 | E9: =SUM(E6:E8) -> 3809520 | F9: =SUM(F6:F8) -> 971120 | G9: =AVERAGE(Clean_Data!$Q$2:$Q$118) -> 32560 | H9: =SUM(H6:H8) -> 1
A12: 2. Sales by Category
A13: Category | B13: Orders | C13: Quantity | D13: Gross Sales | E13: Net Sales | F13: Profit | G13: Avg Order Value | H13: Sales Share
A14: Accessories | B14: =COUNTIFS(Clean_Data!$K$2:$K$118,$A14) -> 14 | C14: =SUMIFS(Clean_Data!$G$2:$G$118,Clean_Data!$K$2:$K$118,$A14) -> 73 | D14: =SUMIFS(Clean_Data!$O$2:$O$118,Clean_Data!$K$2:$K$118,$A14) -> 131400 | E14: =SUMIFS(Clean_Data!$Q$2:$Q$118,Clean_Data!$K$2:$K$118,$A14) -> 119970 | F14: =SUMIFS(Clean_Data!$S$2:$S$118,Clean_Data!$K$2:$K$118,$A14) -> 47700 | G14: =IFERROR(AVERAGEIFS(Clean_Data!$Q$2:$Q$118,Clean_Data!$K$2:$K$118,$A14),0) -> 8569.2857 | H14: =IF($E$18=0,0,E14/$E$18) -> 0.031492156
A15: Clothing | B15: =COUNTIFS(Clean_Data!$K$2:$K$118,$A15) -> 24 | C15: =SUMIFS(Clean_Data!$G$2:$G$118,Clean_Data!$K$2:$K$118,$A15) -> 117 | D15: =SUMIFS(Clean_Data!$O$2:$O$118,Clean_Data!$K$2:$K$118,$A15) -> 190400 | E15: =SUMIFS(Clean_Data!$Q$2:$Q$118,Clean_Data!$K$2:$K$118,$A15) -> 174010 | F15: =SUMIFS(Clean_Data!$S$2:$S$118,Clean_Data!$K$2:$K$118,$A15) -> 78810 | G15: =IFERROR(AVERAGEIFS(Clean_Data!$Q$2:$Q$118,Clean_Data!$K$2:$K$118,$A15),0) -> 7250.4167 | H15: =IF($E$18=0,0,E15/$E$18) -> 0.045677671
A16: Electronics | B16: =COUNTIFS(Clean_Data!$K$2:$K$118,$A16) -> 32 | C16: =SUMIFS(Clean_Data!$G$2:$G$118,Clean_Data!$K$2:$K$118,$A16) -> 161 | D16: =SUMIFS(Clean_Data!$O$2:$O$118,Clean_Data!$K$2:$K$118,$A16) -> 2456500 | E16: =SUMIFS(Clean_Data!$Q$2:$Q$118,Clean_Data!$K$2:$K$118,$A16) -> 2352425 | F16: =SUMIFS(Clean_Data!$S$2:$S$118,Clean_Data!$K$2:$K$118,$A16) -> 510050 | G16: =IFERROR(AVERAGEIFS(Clean_Data!$Q$2:$Q$118,Clean_Data!$K$2:$K$118,$A16),0) -> 73513.281 | H16: =IF($E$18=0,0,E16/$E$18) -> 0.61751218
A17: Furniture | B17: =COUNTIFS(Clean_Data!$K$2:$K$118,$A17) -> 47 | C17: =SUMIFS(Clean_Data!$G$2:$G$118,Clean_Data!$K$2:$K$118,$A17) -> 195 | D17: =SUMIFS(Clean_Data!$O$2:$O$118,Clean_Data!$K$2:$K$118,$A17) -> 1274700 | E17: =SUMIFS(Clean_Data!$Q$2:$Q$118,Clean_Data!$K$2:$K$118,$A17) -> 1163115 | F17: =SUMIFS(Clean_Data!$S$2:$S$118,Clean_Data!$K$2:$K$118,$A17) -> 334560 | G17: =IFERROR(AVERAGEIFS(Clean_Data!$Q$2:$Q$118,Clean_Data!$K$2:$K$118,$A17),0) -> 24747.128 | H17: =IF($E$18=0,0,E17/$E$18) -> 0.30531799
A18: Total | B18: =SUM(B14:B17) -> 117 | C18: =SUM(C14:C17) -> 546 | D18: =SUM(D14:D17) -> 4053000 | E18: =SUM(E14:E17) -> 3809520 | F18: =SUM(F14:F17) -> 971120 | G18: =AVERAGE(Clean_Data!$Q$2:$Q$118) -> 32560 | H18: =SUM(H14:H17) -> 1
A21: 3. Sales by Product
A22: Product | B22: Orders | C22: Quantity | D22: Gross Sales | E22: Net Sales | F22: Profit | G22: Avg Order Value | H22: Sales Share
A23: Laptop | B23: =COUNTIFS(Clean_Data!$J$2:$J$118,$A23) -> 5 | C23: =SUMIFS(Clean_Data!$G$2:$G$118,Clean_Data!$J$2:$J$118,$A23) -> 26 | D23: =SUMIFS(Clean_Data!$O$2:$O$118,Clean_Data!$J$2:$J$118,$A23) -> 1430000 | E23: =SUMIFS(Clean_Data!$Q$2:$Q$118,Clean_Data!$J$2:$J$118,$A23) -> 1391500 | F23: =SUMIFS(Clean_Data!$S$2:$S$118,Clean_Data!$J$2:$J$118,$A23) -> 319000 | G23: =IFERROR(AVERAGEIFS(Clean_Data!$Q$2:$Q$118,Clean_Data!$J$2:$J$118,$A23),0) -> 278300 | H23: =IF($E$33=0,0,E23/$E$33) -> 0.36526912
A24: Monitor | B24: =COUNTIFS(Clean_Data!$J$2:$J$118,$A24) -> 9 | C24: =SUMIFS(Clean_Data!$G$2:$G$118,Clean_Data!$J$2:$J$118,$A24) -> 42 | D24: =SUMIFS(Clean_Data!$O$2:$O$118,Clean_Data!$J$2:$J$118,$A24) -> 756000 | E24: =SUMIFS(Clean_Data!$Q$2:$Q$118,Clean_Data!$J$2:$J$118,$A24) -> 707400 | F24: =SUMIFS(Clean_Data!$S$2:$S$118,Clean_Data!$J$2:$J$118,$A24) -> 140400 | G24: =IFERROR(AVERAGEIFS(Clean_Data!$Q$2:$Q$118,Clean_Data!$J$2:$J$118,$A24),0) -> 78600 | H24: =IF($E$33=0,0,E24/$E$33) -> 0.18569269
A25: Office Chair | B25: =COUNTIFS(Clean_Data!$J$2:$J$118,$A25) -> 21 | C25: =SUMIFS(Clean_Data!$G$2:$G$118,Clean_Data!$J$2:$J$118,$A25) -> 93 | D25: =SUMIFS(Clean_Data!$O$2:$O$118,Clean_Data!$J$2:$J$118,$A25) -> 697500 | E25: =SUMIFS(Clean_Data!$Q$2:$Q$118,Clean_Data!$J$2:$J$118,$A25) -> 640875 | F25: =SUMIFS(Clean_Data!$S$2:$S$118,Clean_Data!$J$2:$J$118,$A25) -> 187500 | G25: =IFERROR(AVERAGEIFS(Clean_Data!$Q$2:$Q$118,Clean_Data!$J$2:$J$118,$A25),0) -> 30517.857 | H25: =IF($E$33=0,0,E25/$E$33) -> 0.16822986
A26: Desk | B26: =COUNTIFS(Clean_Data!$J$2:$J$118,$A26) -> 8 | C26: =SUMIFS(Clean_Data!$G$2:$G$118,Clean_Data!$J$2:$J$118,$A26) -> 36 | D26: =SUMIFS(Clean_Data!$O$2:$O$118,Clean_Data!$J$2:$J$118,$A26) -> 432000 | E26: =SUMIFS(Clean_Data!$Q$2:$Q$118,Clean_Data!$J$2:$J$118,$A26) -> 387600 | F26: =SUMIFS(Clean_Data!$S$2:$S$118,Clean_Data!$J$2:$J$118,$A26) -> 106800 | G26: =IFERROR(AVERAGEIFS(Clean_Data!$Q$2:$Q$118,Clean_Data!$J$2:$J$118,$A26),0) -> 48450 | H26: =IF($E$33=0,0,E26/$E$33) -> 0.1017451
A27: Table Lamp | B27: =COUNTIFS(Clean_Data!$J$2:$J$118,$A27) -> 18 | C27: =SUMIFS(Clean_Data!$G$2:$G$118,Clean_Data!$J$2:$J$118,$A27) -> 66 | D27: =SUMIFS(Clean_Data!$O$2:$O$118,Clean_Data!$J$2:$J$118,$A27) -> 145200 | E27: =SUMIFS(Clean_Data!$Q$2:$Q$118,Clean_Data!$J$2:$J$118,$A27) -> 134640 | F27: =SUMIFS(Clean_Data!$S$2:$S$118,Clean_Data!$J$2:$J$118,$A27) -> 40260 | G27: =IFERROR(AVERAGEIFS(Clean_Data!$Q$2:$Q$118,Clean_Data!$J$2:$J$118,$A27),0) -> 7480 | H27: =IF($E$33=0,0,E27/$E$33) -> 0.035343035
A28: Headphones | B28: =COUNTIFS(Clean_Data!$J$2:$J$118,$A28) -> 8 | C28: =SUMIFS(Clean_Data!$G$2:$G$118,Clean_Data!$J$2:$J$118,$A28) -> 38 | D28: =SUMIFS(Clean_Data!$O$2:$O$118,Clean_Data!$J$2:$J$118,$A28) -> 133000 | E28: =SUMIFS(Clean_Data!$Q$2:$Q$118,Clean_Data!$J$2:$J$118,$A28) -> 127400 | F28: =SUMIFS(Clean_Data!$S$2:$S$118,Clean_Data!$J$2:$J$118,$A28) -> 27650 | G28: =IFERROR(AVERAGEIFS(Clean_Data!$Q$2:$Q$118,Clean_Data!$J$2:$J$118,$A28),0) -> 15925 | H28: =IF($E$33=0,0,E28/$E$33) -> 0.033442533
A29: Keyboard | B29: =COUNTIFS(Clean_Data!$J$2:$J$118,$A29) -> 10 | C29: =SUMIFS(Clean_Data!$G$2:$G$118,Clean_Data!$J$2:$J$118,$A29) -> 55 | D29: =SUMIFS(Clean_Data!$O$2:$O$118,Clean_Data!$J$2:$J$118,$A29) -> 137500 | E29: =SUMIFS(Clean_Data!$Q$2:$Q$118,Clean_Data!$J$2:$J$118,$A29) -> 126125 | F29: =SUMIFS(Clean_Data!$S$2:$S$118,Clean_Data!$J$2:$J$118,$A29) -> 23000 | G29: =IFERROR(AVERAGEIFS(Clean_Data!$Q$2:$Q$118,Clean_Data!$J$2:$J$118,$A29),0) -> 12612.5 | H29: =IF($E$33=0,0,E29/$E$33) -> 0.033107846
A30: Backpack | B30: =COUNTIFS(Clean_Data!$J$2:$J$118,$A30) -> 14 | C30: =SUMIFS(Clean_Data!$G$2:$G$118,Clean_Data!$J$2:$J$118,$A30) -> 73 | D30: =SUMIFS(Clean_Data!$O$2:$O$118,Clean_Data!$J$2:$J$118,$A30) -> 131400 | E30: =SUMIFS(Clean_Data!$Q$2:$Q$118,Clean_Data!$J$2:$J$118,$A30) -> 119970 | F30: =SUMIFS(Clean_Data!$S$2:$S$118,Clean_Data!$J$2:$J$118,$A30) -> 47700 | G30: =IFERROR(AVERAGEIFS(Clean_Data!$Q$2:$Q$118,Clean_Data!$J$2:$J$118,$A30),0) -> 8569.2857 | H30: =IF($E$33=0,0,E30/$E$33) -> 0.031492156
A31: Jeans | B31: =COUNTIFS(Clean_Data!$J$2:$J$118,$A31) -> 10 | C31: =SUMIFS(Clean_Data!$G$2:$G$118,Clean_Data!$J$2:$J$118,$A31) -> 50 | D31: =SUMIFS(Clean_Data!$O$2:$O$118,Clean_Data!$J$2:$J$118,$A31) -> 110000 | E31: =SUMIFS(Clean_Data!$Q$2:$Q$118,Clean_Data!$J$2:$J$118,$A31) -> 99550 | F31: =SUMIFS(Clean_Data!$S$2:$S$118,Clean_Data!$J$2:$J$118,$A31) -> 44550 | G31: =IFERROR(AVERAGEIFS(Clean_Data!$Q$2:$Q$118,Clean_Data!$J$2:$J$118,$A31),0) -> 9955 | H31: =IF($E$33=0,0,E31/$E$33) -> 0.026131901
A32: T-Shirt | B32: =COUNTIFS(Clean_Data!$J$2:$J$118,$A32) -> 14 | C32: =SUMIFS(Clean_Data!$G$2:$G$118,Clean_Data!$J$2:$J$118,$A32) -> 67 | D32: =SUMIFS(Clean_Data!$O$2:$O$118,Clean_Data!$J$2:$J$118,$A32) -> 80400 | E32: =SUMIFS(Clean_Data!$Q$2:$Q$118,Clean_Data!$J$2:$J$118,$A32) -> 74460 | F32: =SUMIFS(Clean_Data!$S$2:$S$118,Clean_Data!$J$2:$J$118,$A32) -> 34260 | G32: =IFERROR(AVERAGEIFS(Clean_Data!$Q$2:$Q$118,Clean_Data!$J$2:$J$118,$A32),0) -> 5318.5714 | H32: =IF($E$33=0,0,E32/$E$33) -> 0.01954577
A33: Total | B33: =SUM(B23:B32) -> 117 | C33: =SUM(C23:C32) -> 546 | D33: =SUM(D23:D32) -> 4053000 | E33: =SUM(E23:E32) -> 3809520 | F33: =SUM(F23:F32) -> 971120 | G33: =AVERAGE(Clean_Data!$Q$2:$Q$118) -> 32560 | H33: =SUM(H23:H32) -> 1
A36: 4. Sales by Employee
A37: Employee | B37: Orders | C37: Quantity | D37: Gross Sales | E37: Net Sales | F37: Profit | G37: Avg Order Value | H37: Sales Share
A38: Priya | B38: =COUNTIFS(Clean_Data!$M$2:$M$118,$A38) -> 17 | C38: =SUMIFS(Clean_Data!$G$2:$G$118,Clean_Data!$M$2:$M$118,$A38) -> 78 | D38: =SUMIFS(Clean_Data!$O$2:$O$118,Clean_Data!$M$2:$M$118,$A38) -> 851800 | E38: =SUMIFS(Clean_Data!$Q$2:$Q$118,Clean_Data!$M$2:$M$118,$A38) -> 809345 | F38: =SUMIFS(Clean_Data!$S$2:$S$118,Clean_Data!$M$2:$M$118,$A38) -> 195395 | G38: =IFERROR(AVERAGEIFS(Clean_Data!$Q$2:$Q$118,Clean_Data!$M$2:$M$118,$A38),0) -> 47608.529 | H38: =IF($E$46=0,0,E38/$E$46) -> 0.21245327
A39: Hamza | B39: =COUNTIFS(Clean_Data!$M$2:$M$118,$A39) -> 26 | C39: =SUMIFS(Clean_Data!$G$2:$G$118,Clean_Data!$M$2:$M$118,$A39) -> 111 | D39: =SUMIFS(Clean_Data!$O$2:$O$118,Clean_Data!$M$2:$M$118,$A39) -> 828600 | E39: =SUMIFS(Clean_Data!$Q$2:$Q$118,Clean_Data!$M$2:$M$118,$A39) -> 788880 | F39: =SUMIFS(Clean_Data!$S$2:$S$118,Clean_Data!$M$2:$M$118,$A39) -> 201090 | G39: =IFERROR(AVERAGEIFS(Clean_Data!$Q$2:$Q$118,Clean_Data!$M$2:$M$118,$A39),0) -> 30341.538 | H39: =IF($E$46=0,0,E39/$E$46) -> 0.20708121
A40: Sara | B40: =COUNTIFS(Clean_Data!$M$2:$M$118,$A40) -> 16 | C40: =SUMIFS(Clean_Data!$G$2:$G$118,Clean_Data!$M$2:$M$118,$A40) -> 78 | D40: =SUMIFS(Clean_Data!$O$2:$O$118,Clean_Data!$M$2:$M$118,$A40) -> 820000 | E40: =SUMIFS(Clean_Data!$Q$2:$Q$118,Clean_Data!$M$2:$M$118,$A40) -> 775595 | F40: =SUMIFS(Clean_Data!$S$2:$S$118,Clean_Data!$M$2:$M$118,$A40) -> 194945 | G40: =IFERROR(AVERAGEIFS(Clean_Data!$Q$2:$Q$118,Clean_Data!$M$2:$M$118,$A40),0) -> 48474.688 | H40: =IF($E$46=0,0,E40/$E$46) -> 0.20359389
A41: Arman | B41: =COUNTIFS(Clean_Data!$M$2:$M$118,$A41) -> 19 | C41: =SUMIFS(Clean_Data!$G$2:$G$118,Clean_Data!$M$2:$M$118,$A41) -> 92 | D41: =SUMIFS(Clean_Data!$O$2:$O$118,Clean_Data!$M$2:$M$118,$A41) -> 556900 | E41: =SUMIFS(Clean_Data!$Q$2:$Q$118,Clean_Data!$M$2:$M$118,$A41) -> 513875 | F41: =SUMIFS(Clean_Data!$S$2:$S$118,Clean_Data!$M$2:$M$118,$A41) -> 130460 | G41: =IFERROR(AVERAGEIFS(Clean_Data!$Q$2:$Q$118,Clean_Data!$M$2:$M$118,$A41),0) -> 27046.053 | H41: =IF($E$46=0,0,E41/$E$46) -> 0.13489232
A42: Rahul | B42: =COUNTIFS(Clean_Data!$M$2:$M$118,$A42) -> 10 | C42: =SUMIFS(Clean_Data!$G$2:$G$118,Clean_Data!$M$2:$M$118,$A42) -> 50 | D42: =SUMIFS(Clean_Data!$O$2:$O$118,Clean_Data!$M$2:$M$118,$A42) -> 373600 | E42: =SUMIFS(Clean_Data!$Q$2:$Q$118,Clean_Data!$M$2:$M$118,$A42) -> 355500 | F42: =SUMIFS(Clean_Data!$S$2:$S$118,Clean_Data!$M$2:$M$118,$A42) -> 94090 | G42: =IFERROR(AVERAGEIFS(Clean_Data!$Q$2:$Q$118,Clean_Data!$M$2:$M$118,$A42),0) -> 35550 | H42: =IF($E$46=0,0,E42/$E$46) -> 0.093318843
A43: Sana | B43: =COUNTIFS(Clean_Data!$M$2:$M$118,$A43) -> 13 | C43: =SUMIFS(Clean_Data!$G$2:$G$118,Clean_Data!$M$2:$M$118,$A43) -> 63 | D43: =SUMIFS(Clean_Data!$O$2:$O$118,Clean_Data!$M$2:$M$118,$A43) -> 283900 | E43: =SUMIFS(Clean_Data!$Q$2:$Q$118,Clean_Data!$M$2:$M$118,$A43) -> 261915 | F43: =SUMIFS(Clean_Data!$S$2:$S$118,Clean_Data!$M$2:$M$118,$A43) -> 70560 | G43: =IFERROR(AVERAGEIFS(Clean_Data!$Q$2:$Q$118,Clean_Data!$M$2:$M$118,$A43),0) -> 20147.308 | H43: =IF($E$46=0,0,E43/$E$46) -> 0.068752756
A44: Kabir | B44: =COUNTIFS(Clean_Data!$M$2:$M$118,$A44) -> 9 | C44: =SUMIFS(Clean_Data!$G$2:$G$118,Clean_Data!$M$2:$M$118,$A44) -> 45 | D44: =SUMIFS(Clean_Data!$O$2:$O$118,Clean_Data!$M$2:$M$118,$A44) -> 251200 | E44: =SUMIFS(Clean_Data!$Q$2:$Q$118,Clean_Data!$M$2:$M$118,$A44) -> 224160 | F44: =SUMIFS(Clean_Data!$S$2:$S$118,Clean_Data!$M$2:$M$118,$A44) -> 60580 | G44: =IFERROR(AVERAGEIFS(Clean_Data!$Q$2:$Q$118,Clean_Data!$M$2:$M$118,$A44),0) -> 24906.667 | H44: =IF($E$46=0,0,E44/$E$46) -> 0.058842059
A45: Ayesha | B45: =COUNTIFS(Clean_Data!$M$2:$M$118,$A45) -> 7 | C45: =SUMIFS(Clean_Data!$G$2:$G$118,Clean_Data!$M$2:$M$118,$A45) -> 29 | D45: =SUMIFS(Clean_Data!$O$2:$O$118,Clean_Data!$M$2:$M$118,$A45) -> 87000 | E45: =SUMIFS(Clean_Data!$Q$2:$Q$118,Clean_Data!$M$2:$M$118,$A45) -> 80250 | F45: =SUMIFS(Clean_Data!$S$2:$S$118,Clean_Data!$M$2:$M$118,$A45) -> 24000 | G45: =IFERROR(AVERAGEIFS(Clean_Data!$Q$2:$Q$118,Clean_Data!$M$2:$M$118,$A45),0) -> 11464.286 | H45: =IF($E$46=0,0,E45/$E$46) -> 0.021065646
A46: Total | B46: =SUM(B38:B45) -> 117 | C46: =SUM(C38:C45) -> 546 | D46: =SUM(D38:D45) -> 4053000 | E46: =SUM(E38:E45) -> 3809520 | F46: =SUM(F38:F45) -> 971120 | G46: =AVERAGE(Clean_Data!$Q$2:$Q$118) -> 32560 | H46: =SUM(H38:H45) -> 1
A49: 5. Monthly Trend
...

Sheet Product_Master
A1: Product_ID | B1: Product_Name | C1: Category | D1: Unit_Price
A2: P101 | B2: Laptop | C2: Electronics | D2: 55000
A3: P102 | B3: Monitor | C3: Electronics | D3: 18000
A4: P103 | B4: Keyboard | C4: Electronics | D4: 2500
A5: P104 | B5: Office Chair | C5: Furniture | D5: 7500
A6: P105 | B6: Desk | C6: Furniture | D6: 12000
A7: P106 | B7: T-Shirt | C7: Clothing | D7: 1200
A8: P107 | B8: Jeans | C8: Clothing | D8: 2200
A9: P108 | B9: Backpack | C9: Accessories | D9: 1800
A10: P109 | B10: Headphones | C10: Electronics | D10: 3500
A11: P110 | B11: Table Lamp | C11: Furniture | D11: 2200

Sheet Employee_Master
A1: Employee_ID | B1: Employee_Name | C1: Base_City
A2: E001 | B2: Rahul | C2: Lucknow
A3: E002 | B3: Priya | C3: Delhi
A4: E003 | B4: Arman | C4: Mumbai
A5: E004 | B5: Sara | C5: Lucknow
A6: E005 | B6: Hamza | C6: Delhi
A7: E006 | B7: Ayesha | C7: Mumbai
A8: E007 | B8: Kabir | C8: Lucknow
A9: E008 | B9: Sana | C9: Delhi

Sheet Assumptions
A1: Assumptions
A2: Blue cells are inputs. Changing them recalculates Cost and Profit across the workbook.
A4: Category | B4: Cost % of Gross Sales
A5: Electronics | B5: 0.75
A6: Furniture | B6: 0.65
A7: Clothing | B7: 0.5
A8: Accessories | B8: 0.55
A10: Cost = Gross Sales (Quantity x Unit_Price) x category cost %. Cost is based on list price, not discounted price.
A11: Profit = Net Sales - Cost. Net Sales = Gross Sales x (1 - Discount).
A12: These cost percentages are ILLUSTRATIVE ASSUMPTIONS made by the analyst. The file contains no cost data.
A13: Profit figures are therefore only as reliable as these percentages; replace them with real margins when available.

Sheet Data_Quality_Log
A1: Data Quality / Cleaning Log
A2: Issues actually found in the uploaded file, plus checks that passed. Raw_Data keeps the original untouched.
A4: Issue found | B4: Column | C4: Records | D4: Action taken | E4: Reason | F4: Affected IDs / note
A5: Exact duplicate rows | B5: All columns (Order_ID) | C5: 3 | D5: Removed (first occurrence kept) | E5: Same Order_ID with identical values in every field; a repeated entry, not a second sale | F5: O035, O079, O110
A6: Inconsistent capitalization (delhi / mumbai) | B6: City | C6: 5 | D6: Standardized to Proper case | E6: Same city written two ways would split totals
A7: Leading/trailing spaces | B7: City | C7: 7 | D7: Trimmed | E7: Hidden spaces break SUMIFS/COUNTIFS matching
A8: Leading/trailing spaces | B8: Payment_Method | C8: 6 | D8: Trimmed | E8: Hidden spaces create false extra payment categories
A9: Missing Order_ID numbers in sequence | B9: Order_ID | C9: 3 | D9: None - kept as is, flagged | E9: Cannot know if these orders existed; values not invented | F9: O036, O080, O111
A10: Sale city differs from employee Base_City | B10: City vs Employee_Base_City | C10: 21 | D10: Kept; flagged in City_vs_Base column | E10: May be legitimate cross-city sales; City (where sold) is used for city analysis | F10: See Clean_Data col W
A11: No cost data provided | B11: Profit | C11: 117 | D11: Profit calculated with assumed category cost % | E11: Brief asks for profit; cost % are analyst assumptions (Assumptions sheet) | F11: Assumption
A14: Validation checks passed (no action needed)
A15: Check | B15: Column | C15: Records | D15: Result
A16: Blank cells / missing values | B16: All raw columns | C16: 0 | D16: None found
A17: Blank rows or columns | B17: Raw_Data | C17: 0 | D17: None found
A18: Order_Date stored as true dates | B18: Order_Date | C18: 0 | D18: All 120 valid dates, 01-Jan-2026 to 30-Apr-2026
A19: Quantity / Discount numeric and in range | B19: Quantity, Discount | C19: 0 | D19: Quantity 1-8; Discount 0%, 5%, 10%, 15%
A20: Product_ID / Employee_ID found in masters | B20: Product_ID, Employee_ID | C20: 0 | D20: All IDs matched, no orphans
A21: Sales_Provided = Qty x Price x (1 - Discount) | B21: Sales_Provided | C21: 0 | D21: Matched for all rows; Sales_Check column = 0
A22: Existing formulas in source | B22: All sheets | C22: 0 | D22: None present
A25: Record count reconciliation
A26: Original records | C26: =COUNTA(Raw_Data!$A$2:$A$121) -> 120
A27: Duplicates removed | C27: 3
A28: Clean records | C28: =COUNTA(Clean_Data!$A$2:$A$118) -> 117 | D28: =IF(C26-C27=C28,"Reconciles","CHECK") -> Reconciles

Sheet Notes_README
A1: Project Notes / README
A2: E-Commerce Sales Performance Analysis | Source: September_Excel_Capstone_Project.xlsx
A4: SHEETS
A5: Dashboard | B5: KPI cards, 5 charts, City and Category dropdown filters
A6: Analysis | B6: KPI summary, business questions (COUNTIFS/AVERAGEIFS/INDEX-MATCH), written insights
A7: Pivot_Analysis | B7: Formula-based pivot-style tables by City, Category, Product, Employee, Month, Payment, City x Category
A8: Clean_Data | B8: Cleaned orders as an Excel Table (tblSales) with lookup and calculated columns
A9: Raw_Data | B9: Original sales data, unchanged
A10: Product_Master / Employee_Master | B10: Lookup tables from the source file
A11: Assumptions | B11: Category cost % used for Profit (editable)
A12: Data_Quality_Log | B12: Issues found, actions, validation checks
A13: Chart_Data | B13: Helper tables that feed Dashboard charts
A15: CLEANING STEPS
A16: 1 | B16: Trimmed spaces in City and Payment_Method (and ID fields as a precaution)
A17: 2 | B17: Standardized City to Proper case (delhi -> Delhi, mumbai -> Mumbai)
A18: 3 | B18: Removed 3 exact duplicate rows (O035, O079, O110); 120 -> 117 records
A19: 4 | B19: No values were invented; missing Order_IDs and city mismatches are flagged, not changed
A21: KEY FORMULAS
A22: Lookups | B22: INDEX/MATCH on Product_Master and Employee_Master (Product_Name, Category, Unit_Price, Employee_Name, Base_City). Equivalent to XLOOKUP, chosen for compatibility.
A23: Gross Sales | B23: Quantity x Unit_Price
A24: Net Sales | B24: Gross Sales - Gross Sales x Discount
A25: Cost / Profit | B25: Cost = Gross Sales x category cost %; Profit = Net Sales - Cost
A26: Month | B26: DATE(YEAR(Order_Date), MONTH(Order_Date), 1) shown as mmm yyyy
A27: Summaries | B27: SUMIFS, COUNTIFS, AVERAGEIFS on Clean_Data ranges
A29: ASSUMPTIONS
A30: Cost % | B30: Electronics 75%, Furniture 65%, Clothing 50%, Accessories 55% of gross sales. Illustrative; not in source data. Edit on Assumptions sheet.
A31: City analysis | B31: Uses the City where the order was placed, not the employee Base_City
A32: Currency | B32: INR; source gives no currency symbol, assumed Indian Rupees
A34: LIMITATIONS
A35: Pivot tables / slicers | B35: Built with openpyxl, which cannot create native PivotTables or slicers. Equivalent formula-based summary tables and dropdown filters are provided. To add real slicers: click Clean_Data > Table Design > Insert Slicer.
A36: Short period | B36: Only Jan-Apr 2026 (4 months, 117 orders), so trends are indicative only
A37: Profit | B37: Based on assumed cost %, not actual cost
A38: Insights text | B38: Written from current figures; re-check if the data changes

Sheet Chart_Data
A1: Chart_Data
A2: Helper tables feeding the Dashboard charts. They respond to the Dashboard City / Category dropdowns. Do not edit.
A3: City criterion | B3: =IF(#REF!="All","*",#REF!) -> #REF!
A4: Category criterion | B4: =IF(#REF!="All","*",#REF!) -> #REF!
A6: Month | B6: Month Start | C6: Net Sales | D6: Profit
A7: Jan 2026 | B7: 46023 | C7: =SUMIFS(Clean_Data!$Q$2:$Q$118,Clean_Data!$U$2:$U$118,$B7,Clean_Data!$E$2:$E$118,$B$3,Clean_Data!$K$2:$K$118,$B$4) -> 0 | D7: =SUMIFS(Clean_Data!$S$2:$S$118,Clean_Data!$U$2:$U$118,$B7,Clean_Data!$E$2:$E$118,$B$3,Clean_Data!$K$2:$K$118,$B$4) -> 0
A8: Feb 2026 | B8: 46054 | C8: =SUMIFS(Clean_Data!$Q$2:$Q$118,Clean_Data!$U$2:$U$118,$B8,Clean_Data!$E$2:$E$118,$B$3,Clean_Data!$K$2:$K$118,$B$4) -> 0 | D8: =SUMIFS(Clean_Data!$S$2:$S$118,Clean_Data!$U$2:$U$118,$B8,Clean_Data!$E$2:$E$118,$B$3,Clean_Data!$K$2:$K$118,$B$4) -> 0
A9: Mar 2026 | B9: 46082 | C9: =SUMIFS(Clean_Data!$Q$2:$Q$118,Clean_Data!$U$2:$U$118,$B9,Clean_Data!$E$2:$E$118,$B$3,Clean_Data!$K$2:$K$118,$B$4) -> 0 | D9: =SUMIFS(Clean_Data!$S$2:$S$118,Clean_Data!$U$2:$U$118,$B9,Clean_Data!$E$2:$E$118,$B$3,Clean_Data!$K$2:$K$118,$B$4) -> 0
A10: Apr 2026 | B10: 46113 | C10: =SUMIFS(Clean_Data!$Q$2:$Q$118,Clean_Data!$U$2:$U$118,$B10,Clean_Data!$E$2:$E$118,$B$3,Clean_Data!$K$2:$K$118,$B$4) -> 0 | D10: =SUMIFS(Clean_Data!$S$2:$S$118,Clean_Data!$U$2:$U$118,$B10,Clean_Data!$E$2:$E$118,$B$3,Clean_Data!$K$2:$K$118,$B$4) -> 0
A12: Category (City filter) | B12: Net Sales | C12: Profit
A13: Accessories | B13: =SUMIFS(Clean_Data!$Q$2:$Q$118,Clean_Data!$K$2:$K$118,$A13,Clean_Data!$E$2:$E$118,$B$3) -> 0 | C13: =SUMIFS(Clean_Data!$S$2:$S$118,Clean_Data!$K$2:$K$118,$A13,Clean_Data!$E$2:$E$118,$B$3) -> 0
A14: Clothing | B14: =SUMIFS(Clean_Data!$Q$2:$Q$118,Clean_Data!$K$2:$K$118,$A14,Clean_Data!$E$2:$E$118,$B$3) -> 0 | C14: =SUMIFS(Clean_Data!$S$2:$S$118,Clean_Data!$K$2:$K$118,$A14,Clean_Data!$E$2:$E$118,$B$3) -> 0
A15: Electronics | B15: =SUMIFS(Clean_Data!$Q$2:$Q$118,Clean_Data!$K$2:$K$118,$A15,Clean_Data!$E$2:$E$118,$B$3) -> 0 | C15: =SUMIFS(Clean_Data!$S$2:$S$118,Clean_Data!$K$2:$K$118,$A15,Clean_Data!$E$2:$E$118,$B$3) -> 0
A16: Furniture | B16: =SUMIFS(Clean_Data!$Q$2:$Q$118,Clean_Data!$K$2:$K$118,$A16,Clean_Data!$E$2:$E$118,$B$3) -> 0 | C16: =SUMIFS(Clean_Data!$S$2:$S$118,Clean_Data!$K$2:$K$118,$A16,Clean_Data!$E$2:$E$118,$B$3) -> 0
A18: City (Category filter) | B18: Net Sales
A19: Delhi | B19: =SUMIFS(Clean_Data!$Q$2:$Q$118,Clean_Data!$E$2:$E$118,$A19,Clean_Data!$K$2:$K$118,$B$4) -> 0
A20: Lucknow | B20: =SUMIFS(Clean_Data!$Q$2:$Q$118,Clean_Data!$E$2:$E$118,$A20,Clean_Data!$K$2:$K$118,$B$4) -> 0
A21: Mumbai | B21: =SUMIFS(Clean_Data!$Q$2:$Q$118,Clean_Data!$E$2:$E$118,$A21,Clean_Data!$K$2:$K$118,$B$4) -> 0
A23: Product (both filters) | B23: Net Sales
A24: Laptop | B24: =SUMIFS(Clean_Data!$Q$2:$Q$118,Clean_Data!$J$2:$J$118,$A24,Clean_Data!$E$2:$E$118,$B$3,Clean_Data!$K$2:$K$118,$B$4) -> 0
A25: Monitor | B25: =SUMIFS(Clean_Data!$Q$2:$Q$118,Clean_Data!$J$2:$J$118,$A25,Clean_Data!$E$2:$E$118,$B$3,Clean_Data!$K$2:$K$118,$B$4) -> 0
A26: Office Chair | B26: =SUMIFS(Clean_Data!$Q$2:$Q$118,Clean_Data!$J$2:$J$118,$A26,Clean_Data!$E$2:$E$118,$B$3,Clean_Data!$K$2:$K$118,$B$4) -> 0
A27: Desk | B27: =SUMIFS(Clean_Data!$Q$2:$Q$118,Clean_Data!$J$2:$J$118,$A27,Clean_Data!$E$2:$E$118,$B$3,Clean_Data!$K$2:$K$118,$B$4) -> 0
A28: Table Lamp | B28: =SUMIFS(Clean_Data!$Q$2:$Q$118,Clean_Data!$J$2:$J$118,$A28,Clean_Data!$E$2:$E$118,$B$3,Clean_Data!$K$2:$K$118,$B$4) -> 0
A29: Headphones | B29: =SUMIFS(Clean_Data!$Q$2:$Q$118,Clean_Data!$J$2:$J$118,$A29,Clean_Data!$E$2:$E$118,$B$3,Clean_Data!$K$2:$K$118,$B$4) -> 0
A30: Keyboard | B30: =SUMIFS(Clean_Data!$Q$2:$Q$118,Clean_Data!$J$2:$J$118,$A30,Clean_Data!$E$2:$E$118,$B$3,Clean_Data!$K$2:$K$118,$B$4) -> 0
A31: Backpack | B31: =SUMIFS(Clean_Data!$Q$2:$Q$118,Clean_Data!$J$2:$J$118,$A31,Clean_Data!$E$2:$E$118,$B$3,Clean_Data!$K$2:$K$118,$B$4) -> 0
A32: Jeans | B32: =SUMIFS(Clean_Data!$Q$2:$Q$118,Clean_Data!$J$2:$J$118,$A32,Clean_Data!$E$2:$E$118,$B$3,Clean_Data!$K$2:$K$118,$B$4) -> 0
A33: T-Shirt | B33: =SUMIFS(Clean_Data!$Q$2:$Q$118,Clean_Data!$J$2:$J$118,$A33,Clean_Data!$E$2:$E$118,$B$3,Clean_Data!$K$2:$K$118,$B$4) -> 0
A35: Employee (both filters) | B35: Net Sales
A36: Priya | B36: =SUMIFS(Clean_Data!$Q$2:$Q$118,Clean_Data!$M$2:$M$118,$A36,Clean_Data!$E$2:$E$118,$B$3,Clean_Data!$K$2:$K$118,$B$4) -> 0
A37: Hamza | B37: =SUMIFS(Clean_Data!$Q$2:$Q$118,Clean_Data!$M$2:$M$118,$A37,Clean_Data!$E$2:$E$118,$B$3,Clean_Data!$K$2:$K$118,$B$4) -> 0
A38: Sara | B38: =SUMIFS(Clean_Data!$Q$2:$Q$118,Clean_Data!$M$2:$M$118,$A38,Clean_Data!$E$2:$E$118,$B$3,Clean_Data!$K$2:$K$118,$B$4) -> 0
A39: Arman | B39: =SUMIFS(Clean_Data!$Q$2:$Q$118,Clean_Data!$M$2:$M$118,$A39,Clean_Data!$E$2:$E$118,$B$3,Clean_Data!$K$2:$K$118,$B$4) -> 0
A40: Rahul | B40: =SUMIFS(Clean_Data!$Q$2:$Q$118,Clean_Data!$M$2:$M$118,$A40,Clean_Data!$E$2:$E$118,$B$3,Clean_Data!$K$2:$K$118,$B$4) -> 0
A41: Sana | B41: =SUMIFS(Clean_Data!$Q$2:$Q$118,Clean_Data!$M$2:$M$118,$A41,Clean_Data!$E$2:$E$118,$B$3,Clean_Data!$K$2:$K$118,$B$4) -> 0
A42: Kabir | B42: =SUMIFS(Clean_Data!$Q$2:$Q$118,Clean_Data!$M$2:$M$118,$A42,Clean_Data!$E$2:$E$118,$B$3,Clean_Data!$K$2:$K$118,$B$4) -> 0
A43: Ayesha | B43: =SUMIFS(Clean_Data!$Q$2:$Q$118,Clean_Data!$M$2:$M$118,$A43,Clean_Data!$E$2:$E$118,$B$3,Clean_Data!$K$2:$K$118,$B$4) -> 0
